Workbook

Sheet scoring
H1: Please ONLY make changes to the "weight" values!!
B2: HUC12 name | C2: v1 score | D2: add rare terr amph, pnts | E2: add clim, conn | F2: final score | H2: category | I2: weight | J2: highest score
A3: 180102080603 | B3: Kelsey Creek | C3: =($I$3*'combined data& scores'!$P$9)+($I$5*'combined data& scores'!$Q$9)+($I$11*'combined data& scores'!$V$9)+($I$12*'combined data& scores'!$Y$9)+($I$13*'combined data& scores'!$AB$9)+($I$14*'combined data& scores'!$AE$9)+($I$15*'combined data& scores'!$AH$9)+($I$16*'combined data& scores'!$AK$9)+($I$17*'combined data& scores'!$AN$9)+($I$6*'combined data& scores'!$R$9)+($I$7*'combined data& scores'!$S$9)+($I$8*'combined data& scores'!$T$9) -> 16.999 | D3: =($I$9*'combined data& scores'!$L$9)+($I$10*'combined data& scores'!$N$9) -> 2.331 | E3: =($I$4*'combined data& scores'!$F$9)+($I$18*'combined data& scores'!$H$9) -> 5 | F3: =SUM(C3:E3) -> 24.33 | H3: Apr 1 SWE | I3: 1 | J3: 5
A4: 180102080201 | B4: South Fork Scott River | C4: =($I$3*'combined data& scores'!$P$21)+($I$5*'combined data& scores'!$Q$21)+($I$11*'combined data& scores'!$V$21)+($I$12*'combined data& scores'!$Y$21)+($I$13*'combined data& scores'!$AB$21)+($I$14*'combined data& scores'!$AE$21)+($I$15*'combined data& scores'!$AH$21)+($I$16*'combined data& scores'!$AK$21)+($I$17*'combined data& scores'!$AN$21)+($I$6*'combined data& scores'!$R$21)+($I$7*'combined data& scores'!$S$21)+($I$8*'combined data& scores'!$T$21) -> 20.332 | D4: =($I$9*'combined data& scores'!$L$21)+($I$10*'combined data& scores'!$N$21) -> 2.997 | E4: =($I$4*'combined data& scores'!$F$21)+($I$18*'combined data& scores'!$H$21) -> 1 | F4: =SUM(C4:E4) -> 24.329 | H4: Climate Rank | I4: 0 | J4: 5
A5: 180102080103 | B5: Lower East Fork Scott River | C5: =($I$3*'combined data& scores'!$P$11)+($I$5*'combined data& scores'!$Q$11)+($I$11*'combined data& scores'!$V$11)+($I$12*'combined data& scores'!$Y$11)+($I$13*'combined data& scores'!$AB$11)+($I$14*'combined data& scores'!$AE$11)+($I$15*'combined data& scores'!$AH$11)+($I$16*'combined data& scores'!$AK$11)+($I$17*'combined data& scores'!$AN$11)+($I$6*'combined data& scores'!$R$11)+($I$7*'combined data& scores'!$S$11)+($I$8*'combined data& scores'!$T$11) -> 21.332 | D5: =($I$9*'combined data& scores'!$L$11)+($I$10*'combined data& scores'!$N$11) -> 2.997 | E5: =($I$4*'combined data& scores'!$F$11)+($I$18*'combined data& scores'!$H$11) -> 3 | F5: =SUM(C5:E5) -> 27.329 | H5: coho | I5: 0.333 | J5: 5
A6: 180102080101 | B6: Upper East Fork Scott River | C6: =($I$3*'combined data& scores'!$P$25)+($I$5*'combined data& scores'!$Q$25)+($I$11*'combined data& scores'!$V$25)+($I$12*'combined data& scores'!$Y$25)+($I$13*'combined data& scores'!$AB$25)+($I$14*'combined data& scores'!$AE$25)+($I$15*'combined data& scores'!$AH$25)+($I$16*'combined data& scores'!$AK$25)+($I$17*'combined data& scores'!$AN$25)+($I$6*'combined data& scores'!$R$25)+($I$7*'combined data& scores'!$S$25)+($I$8*'combined data& scores'!$T$25) -> 19.332 | D6: =($I$9*'combined data& scores'!$L$25)+($I$10*'combined data& scores'!$N$25) -> 2.664 | E6: =($I$4*'combined data& scores'!$F$25)+($I$18*'combined data& scores'!$H$25) -> 4 | F6: =SUM(C6:E6) -> 25.996 | H6: Cascades frog | I6: 0 | J6: 2
A7: 180102080601 | B7: Canyon Creek | C7: =($I$3*'combined data& scores'!$P$3)+($I$5*'combined data& scores'!$Q$3)+($I$11*'combined data& scores'!$V$3)+($I$12*'combined data& scores'!$Y$3)+($I$13*'combined data& scores'!$AB$3)+($I$14*'combined data& scores'!$AE$3)+($I$15*'combined data& scores'!$AH$3)+($I$16*'combined data& scores'!$AK$3)+($I$17*'combined data& scores'!$AN$3)+($I$6*'combined data& scores'!$R$3)+($I$7*'combined data& scores'!$S$3)+($I$8*'combined data& scores'!$T$3) -> 13.999 | D7: =($I$9*'combined data& scores'!$L$3)+($I$10*'combined data& scores'!$N$3) -> 2.997 | E7: =($I$4*'combined data& scores'!$F$3)+($I$18*'combined data& scores'!$H$3) -> 5 | F7: =SUM(C7:E7) -> 21.996 | H7: aspen | I7: 0 | J7: 2
A8: 180102080402 | B8: Kidder Creek | C8: =($I$3*'combined data& scores'!$P$10)+($I$5*'combined data& scores'!$Q$10)+($I$11*'combined data& scores'!$V$10)+($I$12*'combined data& scores'!$Y$10)+($I$13*'combined data& scores'!$AB$10)+($I$14*'combined data& scores'!$AE$10)+($I$15*'combined data& scores'!$AH$10)+($I$16*'combined data& scores'!$AK$10)+($I$17*'combined data& scores'!$AN$10)+($I$6*'combined data& scores'!$R$10)+($I$7*'combined data& scores'!$S$10)+($I$8*'combined data& scores'!$T$10) -> 20.665 | D8: =($I$9*'combined data& scores'!$L$10)+($I$10*'combined data& scores'!$N$10) -> 1.665 | E8: =($I$4*'combined data& scores'!$F$10)+($I$18*'combined data& scores'!$H$10) -> 1 | F8: =SUM(C8:E8) -> 23.33 | H8: darlingtonia | I8: 0 | J8: 2
A9: 180102080203 | B9: French Creek | C9: =($I$3*'combined data& scores'!$P$6)+($I$5*'combined data& scores'!$Q$6)+($I$11*'combined data& scores'!$V$6)+($I$12*'combined data& scores'!$Y$6)+($I$13*'combined data& scores'!$AB$6)+($I$14*'combined data& scores'!$AE$6)+($I$15*'combined data& scores'!$AH$6)+($I$16*'combined data& scores'!$AK$6)+($I$17*'combined data& scores'!$AN$6)+($I$6*'combined data& scores'!$R$6)+($I$7*'combined data& scores'!$S$6)+($I$8*'combined data& scores'!$T$6) -> 13.332 | D9: =($I$9*'combined data& scores'!$L$6)+($I$10*'combined data& scores'!$N$6) -> 2.997 | E9: =($I$4*'combined data& scores'!$F$6)+($I$18*'combined data& scores'!$H$6) -> 3 | F9: =SUM(C9:E9) -> 19.329 | H9: rare amphibians | I9: 0.333 | J9: 5
A10: 180102080102 | B10: Noyes Valley Creek | C10: =($I$3*'combined data& scores'!$P$16)+($I$5*'combined data& scores'!$Q$16)+($I$11*'combined data& scores'!$V$16)+($I$12*'combined data& scores'!$Y$16)+($I$13*'combined data& scores'!$AB$16)+($I$14*'combined data& scores'!$AE$16)+($I$15*'combined data& scores'!$AH$16)+($I$16*'combined data& scores'!$AK$16)+($I$17*'combined data& scores'!$AN$16)+($I$6*'combined data& scores'!$R$16)+($I$7*'combined data& scores'!$S$16)+($I$8*'combined data& scores'!$T$16) -> 9.333 | D10: =($I$9*'combined data& scores'!$L$16)+($I$10*'combined data& scores'!$N$16) -> 1.332 | E10: =($I$4*'combined data& scores'!$F$16)+($I$18*'combined data& scores'!$H$16) -> 5 | F10: =SUM(C10:E10) -> 15.665 | H10: rare plants | I10: 0.333 | J10: 5
A11: 180102080605 | B11: Mill Creek | C11: =($I$3*'combined data& scores'!$P$15)+($I$5*'combined data& scores'!$Q$15)+($I$11*'combined data& scores'!$V$15)+($I$12*'combined data& scores'!$Y$15)+($I$13*'combined data& scores'!$AB$15)+($I$14*'combined data& scores'!$AE$15)+($I$15*'combined data& scores'!$AH$15)+($I$16*'combined data& scores'!$AK$15)+($I$17*'combined data& scores'!$AN$15)+($I$6*'combined data& scores'!$R$15)+($I$7*'combined data& scores'!$S$15)+($I$8*'combined data& scores'!$T$15) -> 10.999 | D11: =($I$9*'combined data& scores'!$L$15)+($I$10*'combined data& scores'!$N$15) -> 1.665 | E11: =($I$4*'combined data& scores'!$F$15)+($I$18*'combined data& scores'!$H$15) -> 4 | F11: =SUM(C11:E11) -> 16.664 | H11: inventoried meadow | I11: 1 | J11: 5
A12: 180102080205 | B12: Etna Creek | C12: =($I$3*'combined data& scores'!$P$5)+($I$5*'combined data& scores'!$Q$5)+($I$11*'combined data& scores'!$V$5)+($I$12*'combined data& scores'!$Y$5)+($I$13*'combined data& scores'!$AB$5)+($I$14*'combined data& scores'!$AE$5)+($I$15*'combined data& scores'!$AH$5)+($I$16*'combined data& scores'!$AK$5)+($I$17*'combined data& scores'!$AN$5)+($I$6*'combined data& scores'!$R$5)+($I$7*'combined data& scores'!$S$5)+($I$8*'combined data& scores'!$T$5) -> 13.332 | D12: =($I$9*'combined data& scores'!$L$5)+($I$10*'combined data& scores'!$N$5) -> 0.999 | E12: =($I$4*'combined data& scores'!$F$5)+($I$18*'combined data& scores'!$H$5) -> 5 | F12: =SUM(C12:E12) -> 19.331 | H12: meadow with NEPA | I12: 5 | J12: 1
A13: 180102080502 | B13: Shackleford Creek | C13: =($I$3*'combined data& scores'!$P$19)+($I$5*'combined data& scores'!$Q$19)+($I$11*'combined data& scores'!$V$19)+($I$12*'combined data& scores'!$Y$19)+($I$13*'combined data& scores'!$AB$19)+($I$14*'combined data& scores'!$AE$19)+($I$15*'combined data& scores'!$AH$19)+($I$16*'combined data& scores'!$AK$19)+($I$17*'combined data& scores'!$AN$19)+($I$6*'combined data& scores'!$R$19)+($I$7*'combined data& scores'!$S$19)+($I$8*'combined data& scores'!$T$19) -> 18.332 | D13: =($I$9*'combined data& scores'!$L$19)+($I$10*'combined data& scores'!$N$19) -> 2.664 | E13: =($I$4*'combined data& scores'!$F$19)+($I$18*'combined data& scores'!$H$19) -> 1 | F13: =SUM(C13:E13) -> 21.996 | H13: recent fire | I13: 1 | J13: 5
A14: 180102080604 | B14: Tompkins Creek-Scott River | C14: =($I$3*'combined data& scores'!$P$23)+($I$5*'combined data& scores'!$Q$23)+($I$11*'combined data& scores'!$V$23)+($I$12*'combined data& scores'!$Y$23)+($I$13*'combined data& scores'!$AB$23)+($I$14*'combined data& scores'!$AE$23)+($I$15*'combined data& scores'!$AH$23)+($I$16*'combined data& scores'!$AK$23)+($I$17*'combined data& scores'!$AN$23)+($I$6*'combined data& scores'!$R$23)+($I$7*'combined data& scores'!$S$23)+($I$8*'combined data& scores'!$T$23) -> 12.999 | D14: =($I$9*'combined data& scores'!$L$23)+($I$10*'combined data& scores'!$N$23) -> 1.665 | E14: =($I$4*'combined data& scores'!$F$23)+($I$18*'combined data& scores'!$H$23) -> 2 | F14: =SUM(C14:E14) -> 16.664 | H14: LMM high | I14: 0 | J14: 5
A15: 180102080602 | B15: Boulder Creek-Scott River | C15: =($I$3*'combined data& scores'!$P$2)+($I$5*'combined data& scores'!$Q$2)+($I$11*'combined data& scores'!$V$2)+($I$12*'combined data& scores'!$Y$2)+($I$13*'combined data& scores'!$AB$2)+($I$14*'combined data& scores'!$AE$2)+($I$15*'combined data& scores'!$AH$2)+($I$16*'combined data& scores'!$AK$2)+($I$17*'combined data& scores'!$AN$2)+($I$6*'combined data& scores'!$R$2)+($I$7*'combined data& scores'!$S$2)+($I$8*'combined data& scores'!$T$2) -> 14 | D15: =($I$9*'combined data& scores'!$L$2)+($I$10*'combined data& scores'!$N$2) -> 2.331 | E15: =($I$4*'combined data& scores'!$F$2)+($I$18*'combined data& scores'!$H$2) -> 2 | F15: =SUM(C15:E15) -> 18.331 | H15: LMM med | I15: 0 | J15: 5
A16: 180102080401 | B16: Patterson Creek | C16: =($I$3*'combined data& scores'!$P$18)+($I$5*'combined data& scores'!$Q$18)+($I$11*'combined data& scores'!$V$18)+($I$12*'combined data& scores'!$Y$18)+($I$13*'combined data& scores'!$AB$18)+($I$14*'combined data& scores'!$AE$18)+($I$15*'combined data& scores'!$AH$18)+($I$16*'combined data& scores'!$AK$18)+($I$17*'combined data& scores'!$AN$18)+($I$6*'combined data& scores'!$R$18)+($I$7*'combined data& scores'!$S$18)+($I$8*'combined data& scores'!$T$18) -> 15.332 | D16: =($I$9*'combined data& scores'!$L$18)+($I$10*'combined data& scores'!$N$18) -> 1.332 | E16: =($I$4*'combined data& scores'!$F$18)+($I$18*'combined data& scores'!$H$18) -> 1 | F16: =SUM(C16:E16) -> 17.664 | H16: EFM land | I16: 1 | J16: 5
A17: 180102080606 | B17: Town of Scott Bar-Scott River | C17: =($I$3*'combined data& scores'!$P$24)+($I$5*'combined data& scores'!$Q$24)+($I$11*'combined data& scores'!$V$24)+($I$12*'combined data& scores'!$Y$24)+($I$13*'combined data& scores'!$AB$24)+($I$14*'combined data& scores'!$AE$24)+($I$15*'combined data& scores'!$AH$24)+($I$16*'combined data& scores'!$AK$24)+($I$17*'combined data& scores'!$AN$24)+($I$6*'combined data& scores'!$R$24)+($I$7*'combined data& scores'!$S$24)+($I$8*'combined data& scores'!$T$24) -> 10.666 | D17: =($I$9*'combined data& scores'!$L$24)+($I$10*'combined data& scores'!$N$24) -> 1.665 | E17: =($I$4*'combined data& scores'!$F$24)+($I$18*'combined data& scores'!$H$24) -> 2 | F17: =SUM(C17:E17) -> 14.331 | H17: Federal land | I17: 1 | J17: 5
A18: 180102080204 | B18: Sugar Creek-Scott River | C18: =($I$3*'combined data& scores'!$P$22)+($I$5*'combined data& scores'!$Q$22)+($I$11*'combined data& scores'!$V$22)+($I$12*'combined data& scores'!$Y$22)+($I$13*'combined data& scores'!$AB$22)+($I$14*'combined data& scores'!$AE$22)+($I$15*'combined data& scores'!$AH$22)+($I$16*'combined data& scores'!$AK$22)+($I$17*'combined data& scores'!$AN$22)+($I$6*'combined data& scores'!$R$22)+($I$7*'combined data& scores'!$S$22)+($I$8*'combined data& scores'!$T$22) -> 11.332 | D18: =($I$9*'combined data& scores'!$L$22)+($I$10*'combined data& scores'!$N$22) -> 2.331 | E18: =($I$4*'combined data& scores'!$F$22)+($I$18*'combined data& scores'!$H$22) -> 3 | F18: =SUM(C18:E18) -> 16.663 | H18: connectivity rank | I18: 1 | J18: 5
A19: 180102080206 | B19: Clark Creek-Scott River | C19: =($I$3*'combined data& scores'!$P$4)+($I$5*'combined data& scores'!$Q$4)+($I$11*'combined data& scores'!$V$4)+($I$12*'combined data& scores'!$Y$4)+($I$13*'combined data& scores'!$AB$4)+($I$14*'combined data& scores'!$AE$4)+($I$15*'combined data& scores'!$AH$4)+($I$16*'combined data& scores'!$AK$4)+($I$17*'combined data& scores'!$AN$4)+($I$6*'combined data& scores'!$R$4)+($I$7*'combined data& scores'!$S$4)+($I$8*'combined data& scores'!$T$4) -> 5 | D19: =($I$9*'combined data& scores'!$L$4)+($I$10*'combined data& scores'!$N$4) -> 1.332 | E19: =($I$4*'combined data& scores'!$F$4)+($I$18*'combined data& scores'!$H$4) -> 5 | F19: =SUM(C19:E19) -> 11.332
A20: 180102080301 | B20: Upper Moffett Creek | C20: =($I$3*'combined data& scores'!$P$26)+($I$5*'combined data& scores'!$Q$26)+($I$11*'combined data& scores'!$V$26)+($I$12*'combined data& scores'!$Y$26)+($I$13*'combined data& scores'!$AB$26)+($I$14*'combined data& scores'!$AE$26)+($I$15*'combined data& scores'!$AH$26)+($I$16*'combined data& scores'!$AK$26)+($I$17*'combined data& scores'!$AN$26)+($I$6*'combined data& scores'!$R$26)+($I$7*'combined data& scores'!$S$26)+($I$8*'combined data& scores'!$T$26) -> 7 | D20: =($I$9*'combined data& scores'!$L$26)+($I$10*'combined data& scores'!$N$26) -> 0.333 | E20: =($I$4*'combined data& scores'!$F$26)+($I$18*'combined data& scores'!$H$26) -> 3 | F20: =SUM(C20:E20) -> 10.333
A21: 180102080302 | B21: McAdam Creek | C21: =($I$3*'combined data& scores'!$P$13)+($I$5*'combined data& scores'!$Q$13)+($I$11*'combined data& scores'!$V$13)+($I$12*'combined data& scores'!$Y$13)+($I$13*'combined data& scores'!$AB$13)+($I$14*'combined data& scores'!$AE$13)+($I$15*'combined data& scores'!$AH$13)+($I$16*'combined data& scores'!$AK$13)+($I$17*'combined data& scores'!$AN$13)+($I$6*'combined data& scores'!$R$13)+($I$7*'combined data& scores'!$S$13)+($I$8*'combined data& scores'!$T$13) -> 8 | D21: =($I$9*'combined data& scores'!$L$13)+($I$10*'combined data& scores'!$N$13) -> 1.332 | E21: =($I$4*'combined data& scores'!$F$13)+($I$18*'combined data& scores'!$H$13) -> 3 | F21: =SUM(C21:E21) -> 12.332
A22: 180102080504 | B22: Sniktaw Creek-Scott River | C22: =($I$3*'combined data& scores'!$P$20)+($I$5*'combined data& scores'!$Q$20)+($I$11*'combined data& scores'!$V$20)+($I$12*'combined data& scores'!$Y$20)+($I$13*'combined data& scores'!$AB$20)+($I$14*'combined data& scores'!$AE$20)+($I$15*'combined data& scores'!$AH$20)+($I$16*'combined data& scores'!$AK$20)+($I$17*'combined data& scores'!$AN$20)+($I$6*'combined data& scores'!$R$20)+($I$7*'combined data& scores'!$S$20)+($I$8*'combined data& scores'!$T$20) -> 8 | D22: =($I$9*'combined data& scores'!$L$20)+($I$10*'combined data& scores'!$N$20) -> 1.332 | E22: =($I$4*'combined data& scores'!$F$20)+($I$18*'combined data& scores'!$H$20) -> 4 | F22: =SUM(C22:E22) -> 13.332
A23: 180102080501 | B23: Indian Creek | C23: =($I$3*'combined data& scores'!$P$8)+($I$5*'combined data& scores'!$Q$8)+($I$11*'combined data& scores'!$V$8)+($I$12*'combined data& scores'!$Y$8)+($I$13*'combined data& scores'!$AB$8)+($I$14*'combined data& scores'!$AE$8)+($I$15*'combined data& scores'!$AH$8)+($I$16*'combined data& scores'!$AK$8)+($I$17*'combined data& scores'!$AN$8)+($I$6*'combined data& scores'!$R$8)+($I$7*'combined data& scores'!$S$8)+($I$8*'combined data& scores'!$T$8) -> 8 | D23: =($I$9*'combined data& scores'!$L$8)+($I$10*'combined data& scores'!$N$8) -> 1.332 | E23: =($I$4*'combined data& scores'!$F$8)+($I$18*'combined data& scores'!$H$8) -> 2 | F23: =SUM(C23:E23) -> 11.332
A24: 180102080303 | B24: Lower Moffett Creek | C24: =($I$3*'combined data& scores'!$P$12)+($I$5*'combined data& scores'!$Q$12)+($I$11*'combined data& scores'!$V$12)+($I$12*'combined data& scores'!$Y$12)+($I$13*'combined data& scores'!$AB$12)+($I$14*'combined data& scores'!$AE$12)+($I$15*'combined data& scores'!$AH$12)+($I$16*'combined data& scores'!$AK$12)+($I$17*'combined data& scores'!$AN$12)+($I$6*'combined data& scores'!$R$12)+($I$7*'combined data& scores'!$S$12)+($I$8*'combined data& scores'!$T$12) -> 3.333 | D24: =($I$9*'combined data& scores'!$L$12)+($I$10*'combined data& scores'!$N$12) -> 1.332 | E24: =($I$4*'combined data& scores'!$F$12)+($I$18*'combined data& scores'!$H$12) -> 4 | F24: =SUM(C24:E24) -> 8.665
A25: 180102080202 | B25: McConaughy Gulch | C25: =($I$3*'combined data& scores'!$P$14)+($I$5*'combined data& scores'!$Q$14)+($I$11*'combined data& scores'!$V$14)+($I$12*'combined data& scores'!$Y$14)+($I$13*'combined data& scores'!$AB$14)+($I$14*'combined data& scores'!$AE$14)+($I$15*'combined data& scores'!$AH$14)+($I$16*'combined data& scores'!$AK$14)+($I$17*'combined data& scores'!$AN$14)+($I$6*'combined data& scores'!$R$14)+($I$7*'combined data& scores'!$S$14)+($I$8*'combined data& scores'!$T$14) -> 1 | D25: =($I$9*'combined data& scores'!$L$14)+($I$10*'combined data& scores'!$N$14) -> 0.333 | E25: =($I$4*'combined data& scores'!$F$14)+($I$18*'combined data& scores'!$H$14) -> 5 | F25: =SUM(C25:E25) -> 6.333
A26: 180102080503 | B26: Oro Fino Creek-Scott River | C26: =($I$3*'combined data& scores'!$P$17)+($I$5*'combined data& scores'!$Q$17)+($I$11*'combined data& scores'!$V$17)+($I$12*'combined data& scores'!$Y$17)+($I$13*'combined data& scores'!$AB$17)+($I$14*'combined data& scores'!$AE$17)+($I$15*'combined data& scores'!$AH$17)+($I$16*'combined data& scores'!$AK$17)+($I$17*'combined data& scores'!$AN$17)+($I$6*'combined data& scores'!$R$17)+($I$7*'combined data& scores'!$S$17)+($I$8*'combined data& scores'!$T$17) -> 4 | D26: =($I$9*'combined data& scores'!$L$17)+($I$10*'combined data& scores'!$N$17) -> 0.999 | E26: =($I$4*'combined data& scores'!$F$17)+($I$18*'combined data& scores'!$H$17) -> 2 | F26: =SUM(C26:E26) -> 6.999
A27: 180102080403 | B27: Hamlin Gulch-Scott River | C27: =($I$3*'combined data& scores'!$P$7)+($I$5*'combined data& scores'!$Q$7)+($I$11*'combined data& scores'!$V$7)+($I$12*'combined data& scores'!$Y$7)+($I$13*'combined data& scores'!$AB$7)+($I$14*'combined data& scores'!$AE$7)+($I$15*'combined data& scores'!$AH$7)+($I$16*'combined data& scores'!$AK$7)+($I$17*'combined data& scores'!$AN$7)+($I$6*'combined data& scores'!$R$7)+($I$7*'combined data& scores'!$S$7)+($I$8*'combined data& scores'!$T$7) -> 1 | D27: =($I$9*'combined data& scores'!$L$7)+($I$10*'combined data& scores'!$N$7) -> 0.666 | E27: =($I$4*'combined data& scores'!$F$7)+($I$18*'combined data& scores'!$H$7) -> 1 | F27: =SUM(C27:E27) -> 2.666
H28: Apr 1 SWE | I28: 1 | J28: 1 | K28: Lower East Fork Scott River
H29: coho | I29: 0.333 | J29: 2 | K29: South Fork Scott River
H30: Cascades frog | I30: 0 | J30: 3 | K30: Upper East Fork Scott River
H31: aspen | I31: 0 | J31: 4 | K31: Kelsey Creek
H32: darlingtonia | I32: 0 | J32: 5 | K32: Kidder Creek
H33: rare amphibians | I33: 0.333 | J33: 6 | K33: Canyon Creek
H34: rare plants | I34: 0.333 | J34: 7 | K34: Shackleford Creek
H35: inventoried meadow | I35: 1 | J35: 8 | K35: Tompkins Creek-Scott River
H36: meadow with NEPA | I36: 5 | J36: 9 | K36: French Creek
H37: recent fire | I37: 1 | J37: 10 | K37: Boulder Creek-Scott River
H38: LMM high | I38: 0
H39: LMM med | I39: 0
H40: EFM land | I40: 0
...

Sheet combined data& scores
A1: huccode | B1: HUC12 name | C1: HUC 12 area (ac) | E1: SUM of ClimRankAve ByArea | F1: ClimRank Jenks | G1: SUM of ConnRankAveByArea | H1: ConnRank Jenks | I1: SUM of RareCountAveByArea | K1: SUM of RareAmphAveByArea | L1: RareAmphJenks score | M1: SUM of RarePlantAveByArea | N1: RarePlants Jenks score | O1: Apr1SWE | P1: Apr1SWE Jenks score | Q1: Coho score | R1: Cascades frog score | S1: aspen score | T1: darlingtonia score | U1: Inventoried MdwPercent (/100) | V1: Inventoried MdwPercent (/100) Jenks | W1: inventoried mdw acres | X1: MdwNEPA percent | Y1: MdwNEPA percent Jenks | Z1: MdwNEPA Ac | AA1: Fire percent | AB1: Fire percent Jenks | AC1: Fire Ac | AD1: LMMhigh percent | AE1: LMMhigh percent Jenks | AF1: LMMhigh Ac | AG1: LMMmed Percent | AH1: LMMmed Percent Jenks | AI1: LMMmed Ac | AJ1: EFM percent | AK1: EFM percent Jenks | AL1: EFM_Ac | AM1: Federal Land Percent | AN1: Federal Land Percent Jenks | AO1: Feds_Ac
A2: 180102080602 | B2: Boulder Creek-Scott River | C2: 12839.32 | E2: 4.6837981 | F2: 5 | G2: 2.7095413 | H2: 2 | I2: 7.4028319 | K2: 1.3531287 | L2: 4 | M2: 1.6780317 | N2: 3 | O2: 84.481954 | P2: 3 | Q2: =biodiversity!$G$2 -> 0 | R2: =biodiversity!$I$2 -> 0 | S2: =biodiversity!$H$2 -> 2 | T2: =biodiversity!$J$2 -> 0 | U2: 0.01233 | V2: 3 | W2: 158.28 | X2: 0 | Y2: 0 | AA2: 0.00387982 | AB2: 1 | AC2: 49.814251 | AD2: 0.0031928964 | AE2: 4 | AF2: 40.994619 | AG2: 0.013736608 | AH2: 3 | AI2: 176.3687 | AJ2: 0.15986238 | AK2: 3 | AL2: 2052.5242 | AM2: 0.5452697 | AN2: 4 | AO2: 7000.8922
A3: 180102080601 | B3: Canyon Creek | C3: 15834.17 | E3: 4.1399337 | F3: 4 | G3: 3.2483895 | H3: 5 | I3: 7.9576799 | K3: 1.9849958 | L3: 5 | M3: 3.6389547 | N3: 4 | O3: 404.53402 | P3: 5 | Q3: =biodiversity!$G$3 -> 3 | R3: =biodiversity!$I$3 -> 2 | S3: =biodiversity!$H$3 -> 2 | T3: =biodiversity!$J$3 -> 0 | U3: 0.00758 | V3: 2 | W3: 120 | X3: 0 | Y3: 0 | AA3: 0.013528107 | AB3: 1 | AC3: 214.20634 | AD3: 0.0078450204 | AE3: 5 | AF3: 124.21939 | AG3: 0.031217554 | AH3: 5 | AI3: 494.30406 | AJ3: 0 | AK3: 0 | AM3: 0.98498019 | AN3: 5 | AO3: 15596.344
A4: 180102080206 | B4: Clark Creek-Scott River | C4: 10279.36 | E4: 2.6140907 | F4: 2 | G4: 3.2066727 | H4: 5 | I4: 3.1435936 | K4: 0.11357276 | L4: 2 | M4: 0.94141786 | N4: 2 | O4: 20.329404 | P4: 1 | Q4: =biodiversity!$G$4 -> 0 | R4: =biodiversity!$I$4 -> 0 | S4: =biodiversity!$H$4 -> 0 | T4: =biodiversity!$J$4 -> 0 | U4: 6e-05 | V4: 1 | W4: 0.58 | X4: 0 | Y4: 0 | AA4: 0 | AB4: 1 | AD4: 0.00029636074 | AE4: 1 | AF4: 3.0463987 | AG4: 0.0060218637 | AH4: 2 | AI4: 61.900904 | AJ4: 0.039953992 | AK4: 1 | AL4: 410.70147 | AM4: 0.016174491 | AN4: 1 | AO4: 166.26342
A5: 180102080205 | B5: Etna Creek | C5: 17245.11 | E5: 4.5260758 | F5: 5 | G5: 3.1612499 | H5: 5 | I5: 2.782797 | K5: 0.31071744 | L5: 2 | M5: 0.42448346 | N5: 1 | O5: 184.55855 | P5: 4 | Q5: =biodiversity!$G$5 -> 4 | R5: =biodiversity!$I$5 -> 2 | S5: =biodiversity!$H$5 -> 2 | T5: =biodiversity!$J$5 -> 0 | U5: 0.00323 | V5: 1 | W5: 55.78 | X5: 0 | Y5: 0 | AA5: 0 | AB5: 1 | AD5: 0.0010775263 | AE5: 2 | AF5: 18.58206 | AG5: 0.0068981661 | AH5: 2 | AI5: 118.95963 | AJ5: 0.13626987 | AK5: 2 | AL5: 2349.989 | AM5: 0.4514524 | AN5: 4 | AO5: 7785.3462
A6: 180102080203 | B6: French Creek | C6: 21309.9 | E6: 4.1562558 | F6: 4 | G6: 2.9213091 | H6: 3 | I6: 6.7279751 | K6: 1.9802349 | L6: 5 | M6: 2.6640403 | N6: 4 | O6: 148.43709 | P6: 4 | Q6: =biodiversity!$G$6 -> 4 | R6: =biodiversity!$I$6 -> 2 | S6: =biodiversity!$H$6 -> 2 | T6: =biodiversity!$J$6 -> 2 | U6: 0.00727 | V6: 2 | W6: 154.95 | X6: 0 | Y6: 0 | AA6: 0.00094488597 | AB6: 1 | AC6: 20.135426 | AD6: 0.0088010186 | AE6: 5 | AF6: 187.54883 | AG6: 0.038048374 | AH6: 5 | AI6: 810.80704 | AJ6: 0.13528413 | AK6: 2 | AL6: 2882.8913 | AM6: 0.28344837 | AN6: 3 | AO6: 6040.2565
A7: 180102080403 | B7: Hamlin Gulch-Scott River | C7: 32372.57 | E7: 1.5193228 | F7: 1 | G7: 2.2747626 | H7: 1 | I7: 2.2402015 | K7: 0 | L7: 0 | M7: 0.68635705 | N7: 2 | O7: 1.3513042 | P7: 1 | Q7: =biodiversity!$G$7 -> 0 | R7: =biodiversity!$I$7 -> 0 | S7: =biodiversity!$H$7 -> 0 | T7: =biodiversity!$J$7 -> 0 | U7: 0 | V7: 0 | W7: 0 | X7: 0 | Y7: 0 | AA7: 0 | AB7: 0 | AD7: 9.7796646e-05 | AE7: 1 | AF7: 3.1659288 | AG7: 0.0012578775 | AH7: 1 | AI7: 40.720728 | AJ7: 0 | AK7: 0 | AM7: 0 | AN7: 0
A8: 180102080501 | B8: Indian Creek | C8: 11697.71 | E8: 3.816556 | F8: 3 | G8: 2.6421271 | H8: 2 | I8: 2.9250172 | K8: 0.11841473 | L8: 2 | M8: 0.72865204 | N8: 2 | O8: 29.03236 | P8: 1 | Q8: =biodiversity!$G$8 -> 0 | R8: =biodiversity!$I$8 -> 0 | S8: =biodiversity!$H$8 -> 0 | T8: =biodiversity!$J$8 -> 0 | U8: 0.00105 | V8: 1 | W8: 12.27 | X8: 0 | Y8: 0 | AA8: 0.029357473 | AB8: 2 | AC8: 343.41521 | AD8: 0.0011246671 | AE8: 2 | AF8: 13.156029 | AG8: 0.012617011 | AH8: 3 | AI8: 147.59013 | AJ8: 0 | AK8: 0 | AM8: 0.68948082 | AN8: 4 | AO8: 8065.3467
A9: 180102080603 | B9: Kelsey Creek | C9: 11383.9 | E9: 3.9632707 | F9: 4 | G9: 3.3543321 | H9: 5 | I9: 4.6626454 | K9: 1.5011968 | L9: 4 | M9: 1.4185415 | N9: 3 | O9: 374.5173 | P9: 5 | Q9: =biodiversity!$G$9 -> 3 | R9: =biodiversity!$I$9 -> 0 | S9: =biodiversity!$H$9 -> 0 | T9: =biodiversity!$J$9 -> 0 | U9: 0.07226 | V9: 5 | W9: 822.65 | X9: 0 | Y9: 0 | AA9: 0.0069442643 | AB9: 1 | AC9: 79.052811 | AD9: 0.0016938801 | AE9: 3 | AF9: 19.282961 | AG9: 0.011326648 | AH9: 3 | AI9: 128.94143 | AJ9: 0 | AK9: 0 | AM9: 0.99207274 | AN9: 5 | AO9: 11293.657
A10: 180102080402 | B10: Kidder Creek | C10: 22246.41 | E10: 4.1835143 | F10: 4 | G10: 2.1917063 | H10: 1 | I10: 3.161369 | K10: 0.90176413 | L10: 3 | M10: 0.62774109 | N10: 2 | O10: 174.06261 | P10: 4 | Q10: =biodiversity!$G$10 -> 5 | R10: =biodiversity!$I$10 -> 2 | S10: =biodiversity!$H$10 -> 2 | T10: =biodiversity!$J$10 -> 0 | U10: 0.00569 | V10: 2 | W10: 126.59 | X10: 0 | Y10: 0 | AA10: 0.41747045 | AB10: 5 | AC10: 9287.2188 | AD10: 0.0015135837 | AE10: 3 | AF10: 33.671805 | AG10: 0.0076451673 | AH10: 2 | AI10: 170.07753 | AJ10: 0.31705555 | AK10: 5 | AL10: 7053.3477 | AM10: 0.36052037 | AN10: 3 | AO10: 8020.2839
A11: 180102080103 | B11: Lower East Fork Scott River | C11: 20388.22 | E11: 4.0464846 | F11: 4 | G11: 2.8852589 | H11: 3 | I11: 10.603879 | K11: 1.3866773 | L11: 4 | M11: 5.7670778 | N11: 5 | O11: 272.13423 | P11: 5 | Q11: =biodiversity!$G$11 -> 4 | R11: =biodiversity!$I$11 -> 2 | S11: =biodiversity!$H$11 -> 0 | T11: =biodiversity!$J$11 -> 2 | U11: 0.01051 | V11: 3 | W11: 214.21 | X11: 0.035781058 | Y11: 1 | Z11: 729.51209 | AA11: 0.056504839 | AB11: 3 | AC11: 1152.0331 | AD11: 0.0034850989 | AE11: 4 | AF11: 71.054962 | AG11: 0.019755658 | AH11: 4 | AI11: 402.78271 | AJ11: 0 | AK11: 0 | AM11: 0.50294712 | AN11: 4 | AO11: 10254.197
A12: 180102080303 | B12: Lower Moffett Creek | C12: 29899.1 | E12: 2.9870646 | F12: 2 | G12: 3.1247643 | H12: 4 | I12: 2.7954061 | K12: 0.0027404052 | L12: 1 | M12: 1.5036736 | N12: 3 | O12: 18.699645 | P12: 1 | Q12: =biodiversity!$G$12 -> 1 | R12: =biodiversity!$I$12 -> 0 | S12: =biodiversity!$H$12 -> 0 | T12: =biodiversity!$J$12 -> 0 | U12: 0.00172 | V12: 1 | W12: 51.28 | X12: 0 | Y12: 0 | AA12: 0 | AB12: 0 | AD12: 0.0012105397 | AE12: 2 | AF12: 36.194046 | AG12: 0.0077912377 | AH12: 2 | AI12: 232.95099 | AJ12: 0 | AK12: 0 | AM12: 0.073582681 | AN12: 1 | AO12: 2200.0559
A13: 180102080302 | B13: McAdam Creek | C13: 17217.93 | E13: 3.8746648 | F13: 3 | G13: 2.9667152 | H13: 3 | I13: 4.4420195 | K13: 0.0030730321 | L13: 1 | M13: 1.9082796 | N13: 3 | O13: 25.962269 | P13: 1 | Q13: =biodiversity!$G$13 -> 0 | R13: =biodiversity!$I$13 -> 0 | S13: =biodiversity!$H$13 -> 0 | T13: =biodiversity!$J$13 -> 0 | U13: 5e-05 | V13: 1 | W13: 0.8 | X13: 0 | Y13: 0 | AA13: 0.032290483 | AB13: 2 | AC13: 555.97528 | AD13: 0.00035303291 | AE13: 1 | AF13: 6.078496 | AG13: 0.0049265751 | AH13: 1 | AI13: 84.825426 | AJ13: 0 | AK13: 0 | AM13: 0.50661558 | AN13: 4 | AO13: 8722.8715
A14: 180102080202 | B14: McConaughy Gulch | C14: 13333.52 | E14: 1.657715 | F14: 1 | G14: 3.1775259 | H14: 5 | I14: 0.72858875 | K14: 0 | L14: 0 | M14: 0.17285098 | N14: 1 | O14: 16.315549 | P14: 1 | Q14: =biodiversity!$G$14 -> 0 | R14: =biodiversity!$I$14 -> 2 | S14: =biodiversity!$H$14 -> 0 | T14: =biodiversity!$J$14 -> 2 | U14: 0 | V14: 0 | W14: 0 | X14: 0 | Y14: 0 | AA14: 0 | AB14: 0 | AD14: 0.0017394686 | AE14: 3 | AF14: 23.19324 | AG14: 0.018077168 | AH14: 4 | AI14: 241.03229 | AJ14: 0 | AK14: 0 | AM14: 0 | AN14: 0
A15: 180102080605 | B15: Mill Creek | C15: 14294.74 | E15: 4.1958405 | F15: 4 | G15: 3 | H15: 4 | I15: 4.8438907 | K15: 1.5169582 | L15: 4 | M15: 0.3003965 | N15: 1 | O15: 15.308942 | P15: 1 | Q15: =biodiversity!$G$15 -> 3 | R15: =biodiversity!$I$15 -> 0 | S15: =biodiversity!$H$15 -> 0 | T15: =biodiversity!$J$15 -> 0 | U15: 0.00058 | V15: 1 | W15: 8.34 | X15: 0 | Y15: 0 | AA15: 0.27454331 | AB15: 4 | AC15: 3924.5252 | AD15: 0.00015759396 | AE15: 1 | AF15: 2.2527647 | AG15: 0.0043908656 | AH15: 1 | AI15: 62.766282 | AJ15: 0 | AK15: 0 | AM15: 0.47224008 | AN15: 4 | AO15: 6750.5491
A16: 180102080102 | B16: Noyes Valley Creek | C16: 16629.83 | E16: 2.0987635 | F16: 1 | G16: 3.2173709 | H16: 5 | I16: 3.9081754 | K16: 0.012710411 | L16: 1 | M16: 1.4381829 | N16: 3 | O16: 55.93476 | P16: 2 | Q16: =biodiversity!$G$16 -> 1 | R16: =biodiversity!$I$16 -> 2 | S16: =biodiversity!$H$16 -> 0 | T16: =biodiversity!$J$16 -> 2 | U16: 0.00665 | V16: 2 | W16: 110.51 | X16: 0 | Y16: 0 | AA16: 0.19539311 | AB16: 4 | AC16: 3249.3542 | AD16: 0.00098697992 | AE16: 2 | AF16: 16.413308 | AG16: 0.013595984 | AH16: 3 | AI16: 226.09891 | AJ16: 0 | AK16: 0 | AM16: 0.048745089 | AN16: 1 | AO16: 810.62255
A17: 180102080503 | B17: Oro Fino Creek-Scott River | C17: 25340.11 | E17: 3.1695235 | F17: 2 | G17: 2.6687244 | H17: 2 | I17: 2.9972685 | K17: 0.014926853 | L17: 2 | M17: 0.042206598 | N17: 1 | O17: 6.8928598 | P17: 1 | Q17: =biodiversity!$G$17 -> 0 | R17: =biodiversity!$I$17 -> 0 | S17: =biodiversity!$H$17 -> 0 | T17: =biodiversity!$J$17 -> 0 | U17: 2e-05 | V17: 1 | W17: 0.43 | X17: 0 | Y17: 0 | AA17: 0 | AB17: 0 | AD17: 0.00099813162 | AE17: 2 | AF17: 25.292765 | AG17: 0.010594797 | AH17: 3 | AI17: 268.47332 | AJ17: 0 | AK17: 0 | AM17: 0.10635958 | AN17: 2 | AO17: 2695.1634
A18: 180102080401 | B18: Patterson Creek | C18: 24156.5 | E18: 4.5569122 | F18: 5 | G18: 1.7232049 | H18: 1 | I18: 4.3143845 | K18: 0.21743889 | L18: 2 | M18: 0.74920879 | N18: 2 | O18: 51.121725 | P18: 2 | Q18: =biodiversity!$G$18 -> 4 | R18: =biodiversity!$I$18 -> 0 | S18: =biodiversity!$H$18 -> 0 | T18: =biodiversity!$J$18 -> 0 | U18: 0.00013 | V18: 1 | W18: 3.06 | X18: 0 | Y18: 0 | AA18: 0.17302173 | AB18: 4 | AC18: 4179.5995 | AD18: 3.1710871e-05 | AE18: 1 | AF18: 0.76602367 | AG18: 0.0011784337 | AH18: 1 | AI18: 28.466834 | AJ18: 0.35110594 | AK18: 5 | AL18: 8481.4907 | AM18: 0.18246945 | AN18: 2 | AO18: 4407.8232
A19: 180102080502 | B19: Shackleford Creek | C19: 27138.99 | E19: 3.7321617 | F19: 3 | G19: 2.3574017 | H19: 1 | I19: 5.720886 | K19: 1.1724882 | L19: 4 | M19: 2.3777206 | N19: 4 | O19: 176.3099 | P19: 4 | Q19: =biodiversity!$G$19 -> 4 | R19: =biodiversity!$I$19 -> 2 | S19: =biodiversity!$H$19 -> 2 | T19: =biodiversity!$J$19 -> 2 | U19: 0.02694 | V19: 4 | W19: 731.21 | X19: 0 | Y19: 0 | AA19: 0.012187767 | AB19: 1 | AC19: 330.76368 | AD19: 0.0073551347 | AE19: 5 | AF19: 199.61093 | AG19: 0.020466209 | AH19: 4 | AI19: 555.43223 | AJ19: 0.34877894 | AK19: 5 | AL19: 9465.5082 | AM19: 0.35258801 | AN19: 3 | AO19: 9568.8826
A20: 180102080504 | B20: Sniktaw Creek-Scott River | C20: 12263.57 | E20: 3.6955851 | F20: 3 | G20: 3.0857224 | H20: 4 | I20: 3.2296362 | K20: 0.11620083 | L20: 2 | M20: 0.86131348 | N20: 2 | O20: 29.86465 | P20: 1 | Q20: =biodiversity!$G$20 -> 0 | R20: =biodiversity!$I$20 -> 0 | S20: =biodiversity!$H$20 -> 0 | T20: =biodiversity!$J$20 -> 0 | U20: 0.00092 | V20: 1 | W20: 11.25 | X20: 0 | Y20: 0 | AA20: 0.0054490503 | AB20: 1 | AC20: 66.824809 | AD20: 0.00057312245 | AE20: 1 | AF20: 7.0285273 | AG20: 0.00847243 | AH20: 2 | AI20: 103.90224 | AJ20: 0.27521354 | AK20: 4 | AL20: 3375.1005 | AM20: 0.011153575 | AN20: 1 | AO20: 136.78265
A21: 180102080201 | B21: South Fork Scott River | C21: 28174.34 | E21: 4.1850177 | F21: 4 | G21: 2.3474409 | H21: 1 | I21: 7.4217319 | K21: 2.4607877 | L21: 5 | M21: 2.3325633 | N21: 4 | O21: 342.62633 | P21: 5 | Q21: =biodiversity!$G$21 -> 4 | R21: =biodiversity!$I$21 -> 2 | S21: =biodiversity!$H$21 -> 2 | T21: =biodiversity!$J$21 -> 2 | U21: 0.01031 | V21: 3 | W21: 290.41 | X21: 0 | Y21: 0 | AA21: 0.48564116 | AB21: 5 | AC21: 13682.619 | AD21: 0.011651672 | AE21: 5 | AF21: 328.27818 | AG21: 0.0455427 | AH21: 5 | AI21: 1283.1355 | AJ21: 0.022754605 | AK21: 1 | AL21: 641.09598 | AM21: 0.77073422 | AN21: 5 | AO21: 21714.928
A22: 180102080204 | B22: Sugar Creek-Scott River | C22: 24966.98 | E22: 3.2575244 | F22: 2 | G22: 2.8513527 | H22: 3 | I22: 6.3281945 | K22: 1.0435085 | L22: 3 | M22: 3.0193863 | N22: 4 | O22: 83.316363 | P22: 3 | Q22: =biodiversity!$G$22 -> 4 | R22: =biodiversity!$I$22 -> 2 | S22: =biodiversity!$H$22 -> 0 | T22: =biodiversity!$J$22 -> 2 | U22: 0.00112 | V22: 1 | W22: 28.03 | X22: 0 | Y22: 0 | AA22: 0 | AB22: 0 | AD22: 0.0018156037 | AE22: 3 | AF22: 45.330142 | AG22: 0.017059287 | AH22: 4 | AI22: 425.91888 | AJ22: 0.1830695 | AK22: 3 | AL22: 4570.6924 | AM22: 0.28336819 | AN22: 3 | AO22: 7074.848
A23: 180102080604 | B23: Tompkins Creek-Scott River | C23: 17635.53 | E23: 4.5856719 | F23: 5 | G23: 2.4928822 | H23: 2 | I23: 3.6262076 | K23: 1.3314902 | L23: 4 | M23: 0.19131703 | N23: 1 | O23: 90.639206 | P23: 3 | Q23: =biodiversity!$G$23 -> 3 | R23: =biodiversity!$I$23 -> 0 | S23: =biodiversity!$H$23 -> 0 | T23: =biodiversity!$J$23 -> 0 | U23: 0.00044 | V23: 1 | W23: 7.84 | X23: 0 | Y23: 0 | AA23: 0.071371805 | AB23: 3 | AC23: 1258.6796 | AD23: 0.00040023544 | AE23: 1 | AF23: 7.058364 | AG23: 0.0044225355 | AH23: 1 | AI23: 77.993758 | AJ23: 0 | AK23: 0 | AM23: 0.97543286 | AN23: 5 | AO23: 17202.275
A24: 180102080606 | B24: Town of Scott Bar-Scott River | C24: 25690.99 | E24: 4.1188576 | F24: 4 | G24: 2.7301096 | H24: 2 | I24: 4.8983866 | K24: 1.1650266 | L24: 4 | M24: 0.4696656 | N24: 1 | O24: 21.977467 | P24: 1 | Q24: =biodiversity!$G$24 -> 2 | R24: =biodiversity!$I$24 -> 2 | S24: =biodiversity!$H$24 -> 0 | T24: =biodiversity!$J$24 -> 0 | U24: 0.0006 | V24: 1 | W24: 15.52 | X24: 0 | Y24: 0 | AA24: 0.19709372 | AB24: 4 | AC24: 5063.5328 | AD24: 0.0017975055 | AE24: 3 | AF24: 46.179696 | AG24: 0.012180896 | AH24: 3 | AI24: 312.93928 | AJ24: 0 | AK24: 0 | AM24: 0.65923028 | AN24: 4 | AO24: 16936.278
A25: 180102080101 | B25: Upper East Fork Scott River | C25: 36911.8 | E25: 3.4749849 | F25: 3 | G25: 3.0860537 | H25: 4 | I25: 9.2086046 | K25: 0.79133057 | L25: 3 | M25: 4.8928299 | N25: 5 | O25: 300.3572 | P25: 5 | Q25: =biodiversity!$G$25 -> 4 | R25: =biodiversity!$I$25 -> 2 | S25: =biodiversity!$H$25 -> 0 | T25: =biodiversity!$J$25 -> 2 | U25: 0.00671 | V25: 2 | W25: 247.56 | X25: 0.035631875 | Y25: 1 | Z25: 1315.2367 | AA25: 0.074536358 | AB25: 3 | AC25: 2751.2711 | AD25: 0.0086924871 | AE25: 5 | AF25: 320.85534 | AG25: 0.049732677 | AH25: 5 | AI25: 1835.7226 | AJ25: 0 | AK25: 0 | AM25: 0.25214846 | AN25: 3 | AO25: 9307.2537
A26: 180102080301 | B26: Upper Moffett Creek | C26: 31806.71 | E26: 2.840664 | F26: 2 | G26: 2.7978034 | H26: 3 | I26: 1.65439 | K26: 0 | L26: 0 | M26: 0.27974527 | N26: 1 | O26: 37.971468 | P26: 2 | Q26: =biodiversity!$G$26 -> 0 | R26: =biodiversity!$I$26 -> 0 | S26: =biodiversity!$H$26 -> 0 | T26: =biodiversity!$J$26 -> 2 | U26: 0.00014 | V26: 1 | W26: 4.34 | X26: 0 | Y26: 0 | AA26: 0.068353628 | AB26: 3 | AC26: 2174.104 | AD26: 0.0039132146 | AE26: 4 | AF26: 124.46648 | AG26: 0.017368638 | AH26: 4 | AI26: 552.43924 | AJ26: 0 | AK26: 0 | AM26: 0.0049499108 | AN26: 1 | AO26: 157.44038

Sheet FedsByHUC12_Clipped_Merge
A1: OBJECTID_12 | B1: OBJECTID_1 | C1: OBJECTID | D1: APN | E1: GIS_ACRES | F1: Apn_join | G1: Shape_Leng | H1: ASMT | I1: Shape_Le_1 | J1: OBJECTID_2 | K1: Asmt_1 | L1: FeeParcel | M1: Zoning1 | N1: LandUse1 | O1: Neighborho | P1: CurrentDoc | Q1: CurrentD_1 | R1: AssesseeNa | S1: DBA | T1: Address1 | U1: Address2 | V1: Address3 | W1: Address4 | X1: LastOfLand | Y1: LastOfStru | Z1: LastOfFixt | AA1: LastOfFi_1 | AB1: LastOfPPBu | AC1: LastOfPPMH | AD1: LastOfHOXE | AE1: LastOfOthe | AF1: NetAssesse | AG1: LastOfOt_1 | AH1: Street | AI1: StreetNum | AJ1: StreetType | AK1: StreetDire | AL1: SpaceApt | AM1: Community | AN1: Zip | AO1: Sec | AP1: Township | AQ1: Range | AR1: Descr | AS1: LastOfDocN | AT1: RollYear | AU1: TimberPres | AV1: AgPreserve | AW1: Shape_Le_2 | AX1: HUC12 | AY1: Shape_Length | AZ1: Shape_Area
A2: 1 | B2: 26179 | C2: 26179 | D2: 023-280-040 | E2: 157.44038 | F2: 023-280-04 | G2: 10482.108 | H2: 023280040000 | I2: 10482.108 | J2: 18004 | K2: 023280040000 | L2: 023280040000 | N2: 007 | O2: 023 | P2: 1951R0276310 | Q2: 18745 | R2: U S A | X2: 0 | Y2: 0 | Z2: 0 | AA2: 0 | AB2: 0 | AC2: 0 | AD2: 0 | AE2: 0 | AF2: 0 | AO2: 2 | AP2: 42N | AQ2: 8W | AS2: 2016I601 | AT2: 2016 | AU2: No | AV2: No | AW2: 10482.108 | AX2: UpperMoffett_Feds_Clip | AY2: 10482.108 | AZ2: 6857639.6
A3: 2 | B3: 25742 | C3: 25742 | D3: 022-180-110 | E3: 42.819618 | F3: 022-180-11 | G3: 5686.1053 | H3: 022180110000 | I3: 5686.1058 | J3: 16697 | K3: 022180110000 | L3: 022180110000 | N3: 007 | O3: 022 | P3: 1966R0531329 | Q3: 24296 | R3: U S A | X3: 0 | Y3: 0 | Z3: 0 | AA3: 0 | AB3: 0 | AC3: 0 | AD3: 0 | AE3: 0 | AF3: 0 | AO3: 32 | AP3: 41N | AQ3: 7W | AS3: 2016I601 | AT3: 2016 | AU3: No | AV3: No | AW3: 5686.1058 | AX3: UpperEast_Scott_Feds_Clip | AY3: 5686.1058 | AZ3: 1864981.1
A4: 3 | B4: 2855 | C4: 2855 | D4: 022-130-120 | E4: 158.61626 | F4: 022-130-12 | G4: 10514.306 | H4: 022130120000 | I4: 10514.306 | J4: 16644 | K4: 022130120000 | L4: 022130120000 | N4: 007 | O4: 022 | Q4: 40030 | R4: U S A KNF | X4: 0 | Y4: 0 | Z4: 0 | AA4: 0 | AB4: 0 | AC4: 0 | AD4: 0 | AE4: 0 | AF4: 0 | AO4: 11 | AP4: 41N | AQ4: 7W | AS4: 2016I601 | AT4: 2016 | AU4: No | AV4: No | AW4: 10514.306 | AX4: UpperEast_Scott_Feds_Clip | AY4: 10514.306 | AZ4: 6908568.6
A5: 4 | B5: 7625 | C5: 7625 | D5: 031-350-180 | E5: 223.53406 | F5: 031-350-18 | G5: 21234.829 | H5: 031350180000 | I5: 21234.829 | J5: 23392 | K5: 031350180000 | L5: 031350180000 | N5: 007 | O5: 031 | Q5: 40030 | R5: U S A KNF | X5: 0 | Y5: 0 | Z5: 0 | AA5: 0 | AB5: 0 | AC5: 0 | AD5: 0 | AE5: 0 | AF5: 0 | AO5: 16 | AP5: 40N | AQ5: 7W | AS5: 2016I601 | AT5: 2016 | AU5: No | AV5: No | AW5: 21234.829 | AX5: UpperEast_Scott_Feds_Clip | AY5: 16219.271 | AZ5: 9735951.6
A6: 5 | B6: 18621 | C6: 18621 | D6: 022-160-090 | E6: 636.34312 | F6: 022-160-09 | G6: 21059.351 | H6: 022160090000 | I6: 21059.351 | J6: 16684 | K6: 022160090000 | L6: 022160090000 | N6: 007 | O6: 022 | Q6: 40030 | R6: U S A KNF | X6: 0 | Y6: 0 | Z6: 0 | AA6: 0 | AB6: 0 | AC6: 0 | AD6: 0 | AE6: 0 | AF6: 0 | AO6: 24 | AP6: 41N | AQ6: 7W | AS6: 2016I601 | AT6: 2016 | AU6: No | AV6: No | AW6: 21059.351 | AX6: UpperEast_Scott_Feds_Clip | AY6: 21059.351 | AZ6: 27715822
A7: 6 | B7: 20365 | C7: 20365 | D7: 031-350-170 | E7: 351.57956 | F7: 031-350-17 | G7: 18354.363 | H7: 031350170000 | I7: 18354.363 | J7: 23391 | K7: 031350170000 | L7: 031350170000 | N7: 007 | O7: 031 | Q7: 40030 | R7: U S A KNF | X7: 0 | Y7: 0 | Z7: 0 | AA7: 0 | AB7: 0 | AC7: 0 | AD7: 0 | AE7: 0 | AF7: 0 | AO7: 18 | AP7: 40N | AQ7: 7W | AS7: 2016I601 | AT7: 2016 | AU7: No | AV7: No | AW7: 18354.363 | AX7: UpperEast_Scott_Feds_Clip | AY7: 17896.77 | AZ7: 15312682
A8: 7 | B8: 21492 | C8: 21492 | D8: 022-170-070 | E8: 635.74029 | F8: 022-170-07 | G8: 21098.452 | H8: 022170070000 | I8: 21098.452 | J8: 16691 | K8: 022170070000 | L8: 022170070000 | N8: 007 | O8: 022 | Q8: 40030 | R8: U S A KNF | X8: 0 | Y8: 0 | Z8: 0 | AA8: 0 | AB8: 0 | AC8: 0 | AD8: 0 | AE8: 0 | AF8: 0 | AO8: 34 | AP8: 41N | AQ8: 7W | AS8: 2016I601 | AT8: 2016 | AU8: No | AV8: No | AW8: 21098.452 | AX8: UpperEast_Scott_Feds_Clip | AY8: 21098.452 | AZ8: 27689176
A9: 8 | B9: 21545 | C9: 21545 | D9: 022-160-060 | E9: 479.13344 | F9: 022-160-06 | G9: 21091.999 | H9: 022160060000 | I9: 21091.998 | J9: 16681 | K9: 022160060000 | L9: 022160060000 | N9: 007 | O9: 022 | Q9: 40030 | R9: U S A KNF | X9: 0 | Y9: 0 | Z9: 0 | AA9: 0 | AB9: 0 | AC9: 0 | AD9: 0 | AE9: 0 | AF9: 0 | AO9: 14 | AP9: 41N | AQ9: 7W | AS9: 2016I601 | AT9: 2016 | AU9: No | AV9: No | AW9: 21091.998 | AX9: UpperEast_Scott_Feds_Clip | AY9: 21091.998 | AZ9: 20868264
A10: 9 | B10: 21553 | C10: 21553 | D10: 022-160-070 | E10: 323.125 | F10: 022-160-07 | G10: 15876.328 | H10: 022160070000 | I10: 15876.328 | J10: 16682 | K10: 022160070000 | L10: 022160070000 | N10: 007 | O10: 022 | Q10: 40030 | R10: U S A KNF | X10: 0 | Y10: 0 | Z10: 0 | AA10: 0 | AB10: 0 | AC10: 0 | AD10: 0 | AE10: 0 | AF10: 0 | AO10: 13 | AP10: 41N | AQ10: 7W | AS10: 2016I601 | AT10: 2016 | AU10: No | AV10: No | AW10: 15876.328 | AX10: UpperEast_Scott_Feds_Clip | AY10: 15876.328 | AZ10: 14073728
A11: 10 | B11: 22664 | C11: 22664 | D11: 031-410-040 | E11: 180.36754 | F11: 031-410-04 | G11: 13232.16 | H11: 031410040000 | I11: 13232.16 | J11: 23433 | K11: 031410040000 | L11: 031410040000 | N11: 007 | O11: 031 | Q11: 40030 | R11: U S A KNF | X11: 0 | Y11: 0 | Z11: 0 | AA11: 0 | AB11: 0 | AC11: 0 | AD11: 0 | AE11: 0 | AF11: 0 | AO11: 8 | AP11: 40N | AQ11: 6W | AS11: 2016I601 | AT11: 2016 | AU11: No | AV11: No | AW11: 13232.16 | AX11: UpperEast_Scott_Feds_Clip | AY11: 13182.418 | AZ11: 7855746.2
A12: 11 | B12: 22751 | C12: 22751 | D12: 022-130-130 | E12: 648.91318 | F12: 022-130-13 | G12: 21276.923 | H12: 022130130000 | I12: 21276.923 | J12: 16645 | K12: 022130130000 | L12: 022130130000 | N12: 007 | O12: 022 | Q12: 40030 | R12: U S A KNF | X12: 0 | Y12: 0 | Z12: 0 | AA12: 0 | AB12: 0 | AC12: 0 | AD12: 0 | AE12: 0 | AF12: 0 | AO12: 12 | AP12: 41N | AQ12: 7W | AS12: 2016I601 | AT12: 2016 | AU12: No | AV12: No | AW12: 21276.923 | AX12: UpperEast_Scott_Feds_Clip | AY12: 21276.923 | AZ12: 28263538
A13: 12 | B13: 25115 | C13: 25115 | D13: 031-330-060 | E13: 632.67946 | F13: 031-330-06 | G13: 21035.556 | H13: 031330060000 | I13: 21035.557 | J13: 23370 | K13: 031330060000 | L13: 031330060000 | N13: 007 | O13: 031 | Q13: 40030 | R13: U S A KNF | X13: 0 | Y13: 0 | Z13: 0 | AA13: 0 | AB13: 0 | AC13: 0 | AD13: 0 | AE13: 0 | AF13: 0 | AO13: 12 | AP13: 40N | AQ13: 7W | AS13: 2016I601 | AT13: 2016 | AU13: No | AV13: No | AW13: 21035.557 | AX13: UpperEast_Scott_Feds_Clip | AY13: 21035.557 | AZ13: 27555482
A14: 13 | B14: 26376 | C14: 26376 | D14: 022-170-060 | E14: 612.50647 | F14: 022-170-06 | G14: 22004.141 | H14: 022170060000 | I14: 22004.141 | J14: 16690 | K14: 022170060000 | L14: 022170060000 | N14: 007 | O14: 022 | Q14: 40030 | R14: U S A KNF | X14: 0 | Y14: 0 | Z14: 0 | AA14: 0 | AB14: 0 | AC14: 0 | AD14: 0 | AE14: 0 | AF14: 0 | AO14: 26 | AP14: 41N | AQ14: 7W | AS14: 2016I601 | AT14: 2016 | AU14: No | AV14: No | AW14: 22004.141 | AX14: UpperEast_Scott_Feds_Clip | AY14: 22004.141 | AZ14: 26677093
A15: 14 | B15: 29154 | C15: 29154 | D15: 031-360-030 | E15: 251.18196 | F15: 031-360-03 | G15: 20043.718 | H15: 031360030000 | I15: 20043.718 | J15: 23403 | K15: 031360030000 | L15: 031360030000 | N15: 007 | O15: 031 | Q15: 40030 | R15: U S A KNF | X15: 0 | Y15: 0 | Z15: 0 | AA15: 0 | AB15: 0 | AC15: 0 | AD15: 0 | AE15: 0 | AF15: 0 | AO15: 14 | AP15: 40N | AQ15: 7W | AS15: 2016I601 | AT15: 2016 | AU15: No | AV15: No | AW15: 20043.718 | AX15: UpperEast_Scott_Feds_Clip | AY15: 15676.665 | AZ15: 10940631
... A26: 25 | B26: 41685 | C26: 41685 | D26: 031-330-040 | E26: 39.423977 | F26: 031-330-04 | G26: 11289.789 | H26: 031330040000 | I26: 11289.788 | J26: 23368 | K26: 031330040000 | L26: 031330040000 | N26: 007 | O26: 031 | Q26: 40030 | R26: U S A KNF | X26: 0 | Y26: 0 | Z26: 0 | AA26: 0 | AB26: 0 | AC26: 0 | AD26: 0 | AE26: 0 | AF26: 0 | AO26: 2 | AP26: 40N | AQ26: 7W | AS26: 2016I601 | AT26: 2016 | AU26: No | AV26: No | AW26: 11289.788 | AX26: UpperEast_Scott_Feds_Clip | AY26: 11289.788 | AZ26: 1716784.5
A27: 26 | B27: 41737 | C27: 41737 | D27: 031-330-050 | E27: 635.50968 | F27: 031-330-05 | G27: 21055.956 | H27: 031330050000 | I27: 21055.956 | J27: 23369 | K27: 031330050000 | L27: 031330050000 | N27: 007 | O27: 031 | Q27: 40030 | R27: U S A KNF | X27: 0 | Y27: 0 | Z27: 0 | AA27: 0 | AB27: 0 | AC27: 0 | AD27: 0 | AE27: 0 | AF27: 0 | AO27: 10 | AP27: 40N | AS27: 2016I601 | AT27: 2016 | AU27: No | AV27: No | AW27: 21055.956 | AX27: UpperEast_Scott_Feds_Clip | AY27: 21055.956 | AZ27: 27679144
A28: 27 | B28: 41740 | C28: 41740 | D28: 031-410-030 | E28: 46.215845 | F28: 031-410-03 | G28: 11756.007 | H28: 031410030000 | I28: 11756.007 | J28: 23432 | K28: 031410030000 | L28: 031410030000 | N28: 007 | O28: 031 | Q28: 40030 | R28: U S A KNF | X28: 0 | Y28: 0 | Z28: 0 | AA28: 0 | AB28: 0 | AC28: 0 | AD28: 0 | AE28: 0 | AF28: 0 | AO28: 7 | AP28: 40N | AQ28: 6W | AS28: 2016I601 | AT28: 2016 | AU28: No | AV28: No | AW28: 11756.007 | AX28: UpperEast_Scott_Feds_Clip | AY28: 11756.007 | AZ28: 2012407.8
A29: 28 | B29: 30154 | C29: 30154 | D29: 015-300-040 | E29: 35.027561 | F29: 015-300-04 | G29: 7980.4812 | H29: 015300040000 | I29: 7980.482 | J29: 10925 | K29: 015300040000 | L29: 015300040000 | N29: 007 | O29: 015 | P29: 1963R0488168 | Q29: 23118 | R29: U S A | X29: 0 | Y29: 0 | Z29: 0 | AA29: 0 | AB29: 0 | AC29: 0 | AD29: 0 | AE29: 0 | AF29: 0 | AO29: 21,28 | AP29: 45N | AQ29: 10W | AS29: 2016I601 | AT29: 2016 | AU29: No | AV29: No | AW29: 7980.482 | AX29: TownofScottBar_Scott_Feds_Clip | AY29: 7980.482 | AZ29: 1525851.2
A30: 29 | B30: 31919 | C30: 31919 | D30: 015-580-020 | E30: 2.4545424 | F30: 015-580-02 | G30: 1313.082 | H30: 015580020000 | I30: 1313.082 | J30: 11327 | K30: 015580020000 | L30: 015580020000 | N30: 007 | O30: 015 | Q30: 40030 | R30: U S A | X30: 0 | Y30: 0 | Z30: 0 | AA30: 0 | AB30: 0 | AC30: 0 | AD30: 0 | AE30: 0 | AF30: 0 | AO30: 21 | AP30: 45N | AQ30: 10W | AS30: 2016I601 | AT30: 2016 | AU30: No | AV30: No | AW30: 1313.082 | AX30: TownofScottBar_Scott_Feds_Clip | AY30: 1313.082 | AZ30: 106924.14
A31: 30 | B31: 596 | C31: 596 | D31: 015-490-030 | E31: 296.61556 | F31: 015-490-03 | G31: 17586.786 | H31: 015490030000 | I31: 17586.787 | J31: 11142 | K31: 015490030000 | L31: 015490030000 | N31: 007 | O31: 015 | Q31: 40030 | R31: U S A KNF | X31: 0 | Y31: 0 | Z31: 0 | AA31: 0 | AB31: 0 | AC31: 0 | AD31: 0 | AE31: 0 | AF31: 0 | AO31: 17 | AP31: 45N | AQ31: 10W | AS31: 2016I601 | AT31: 2016 | AU31: No | AV31: No | AW31: 17586.787 | AX31: TownofScottBar_Scott_Feds_Clip | AY31: 17586.787 | AZ31: 12921174
A32: 31 | B32: 883 | C32: 883 | D32: 015-290-030 | E32: 310.55001 | F32: 015-290-03 | G32: 15631.045 | H32: 015290030000 | I32: 15631.045 | J32: 10922 | K32: 015290030000 | L32: 015290030000 | N32: 007 | O32: 015 | Q32: 40030 | R32: U S A KNF | X32: 0 | Y32: 0 | Z32: 0 | AA32: 0 | AB32: 0 | AC32: 0 | AD32: 0 | AE32: 0 | AF32: 0 | AO32: 17 | AP32: 45N | AQ32: 10W | AS32: 2016I601 | AT32: 2016 | AU32: No | AV32: No | AW32: 15631.045 | AX32: TownofScottBar_Scott_Feds_Clip | AY32: 15631.045 | AZ32: 13528131
A33: 32 | B33: 891 | C33: 891 | D33: 015-510-230 | E33: 9.3852557 | F33: 015-510-23 | G33: 4974.6615 | H33: 015510230000 | I33: 4974.6619 | J33: 11158 | K33: 015510230000 | L33: 015510230000 | N33: 007 | O33: 015 | Q33: 40030 | R33: U S A KNF | X33: 0 | Y33: 0 | Z33: 0 | AA33: 0 | AB33: 0 | AC33: 0 | AD33: 0 | AE33: 0 | AF33: 0 | AO33: 16 | AP33: 45N | AQ33: 10W | AS33: 2016I601 | AT33: 2016 | AU33: No | AV33: No | AW33: 4974.6619 | AX33: TownofScottBar_Scott_Feds_Clip | AY33: 4974.6619 | AZ33: 408826.52
A34: 33 | B34: 1928 | C34: 1928 | D34: 015-250-080 | E34: 1.0143413 | F34: 015-250-08 | G34: 1568.5315 | H34: 015250080000 | I34: 1568.5314 | J34: 10627 | K34: 015250080000 | L34: 015250080000 | N34: 007 | O34: 015 | Q34: 40030 | R34: U S A KNF | X34: 0 | Y34: 0 | Z34: 0 | AA34: 0 | AB34: 0 | AC34: 0 | AD34: 0 | AE34: 0 | AF34: 0 | AO34: 1 | AP34: 45N | AQ34: 10W | AS34: 2016I601 | AT34: 2016 | AU34: No | AV34: No | AW34: 1568.5314 | AX34: TownofScottBar_Scott_Feds_Clip | AY34: 928.7908 | AZ34: 44187.214
A35: 34 | B35: 3224 | C35: 3224 | D35: 015-170-060 | E35: 623.96004 | F35: 015-170-06 | G35: 20856.341 | H35: 015170060000 | I35: 20856.341 | J35: 10820 | K35: 015170060000 | L35: 015170060000 | N35: 007 | O35: 015 | Q35: 40030 | R35: U S A KNF | X35: 0 | Y35: 0 | Z35: 0 | AA35: 0 | AB35: 0 | AC35: 0 | AD35: 0 | AE35: 0 | AF35: 0 | AO35: 35 | AP35: 45N | AQ35: 11W | AS35: 2016I601 | AT35: 2016 | AU35: No | AV35: No | AW35: 20856.341 | AX35: TownofScottBar_Scott_Feds_Clip | AY35: 20856.341 | AZ35: 27180745
A36: 35 | B36: 3464 | C36: 3464 | D36: 015-250-050 | E36: 372.3946 | F36: 015-250-05 | G36: 16889.912 | H36: 015250050000 | I36: 16889.913 | J36: 10624 | K36: 015250050000 | L36: 015250050000 | N36: 007 | O36: 015 | Q36: 40030 | R36: U S A KNF | X36: 0 | Y36: 0 | Z36: 0 | AA36: 0 | AB36: 0 | AC36: 0 | AD36: 0 | AE36: 0 | AF36: 0 | AO36: 5 | AP36: 45N | AQ36: 10W | AS36: 2016I601 | AT36: 2016 | AU36: No | AV36: No | AW36: 16889.913 | AX36: TownofScottBar_Scott_Feds_Clip | AY36: 15966.821 | AZ36: 16222265
A37: 36 | B37: 4767 | C37: 4767 | D37: 015-160-060 | E37: 477.0631 | F37: 015-160-06 | G37: 20088.146 | H37: 015160060000 | I37: 20088.146 | J37: 10815 | K37: 015160060000 | L37: 015160060000 | N37: 007 | O37: 015 | Q37: 40030 | R37: U S A KNF | X37: 0 | Y37: 0 | Z37: 0 | AA37: 0 | AB37: 0 | AC37: 0 | AD37: 0 | AE37: 0 | AF37: 0 | AO37: 24 | AP37: 45N | AQ37: 11W | AS37: 2016I601 | AT37: 2016 | AU37: No | AV37: No | AW37: 20088.146 | AX37: TownofScottBar_Scott_Feds_Clip | AY37: 20057.93 | AZ37: 20781162
A38: 37 | B38: 4768 | C38: 4768 | D38: 015-290-010 | E38: 602.06727 | F38: 015-290-01 | G38: 20485.517 | H38: 015290010000 | I38: 20485.517 | J38: 10920 | K38: 015290010000 | L38: 015290010000 | N38: 007 | O38: 015 | P38: 1981R0933530 | Q38: 29937 | R38: U S A KNF | X38: 0 | Y38: 0 | Z38: 0 | AA38: 0 | AB38: 0 | AC38: 0 | AD38: 0 | AE38: 0 | AF38: 0 | AO38: 19 | AP38: 45N | AQ38: 10W | AS38: 2016I601 | AT38: 2016 | AU38: No | AV38: No | AW38: 20485.517 | AX38: TownofScottBar_Scott_Feds_Clip | AY38: 20485.517 | AZ38: 26227007
A39: 38 | B39: 4774 | C39: 4774 | D39: 015-300-090 | E39: 408.23498 | F39: 015-300-09 | G39: 31862.735 | H39: 015300090000 | I39: 31862.736 | J39: 10929 | K39: 015300090000 | L39: 015300090000 | N39: 007 | O39: 015 | Q39: 40030 | R39: U S A KNF | X39: 0 | Y39: 0 | Z39: 0 | AA39: 0 | AB39: 0 | AC39: 0 | AD39: 0 | AE39: 0 | AF39: 0 | AO39: 21 | AP39: 45N | AQ39: 10W | AS39: 2016I601 | AT39: 2016 | AU39: No | AV39: No | AW39: 31862.736 | AX39: TownofScottBar_Scott_Feds_Clip | AY39: 30887.918 | AZ39: 17783144
A40: 39 | B40: 5142 | C40: 5142 | D40: 015-190-080 | E40: 117.26603 | F40: 015-190-08 | G40: 15932.47 | H40: 015190080000 | I40: 15932.471 | J40: 10832 | K40: 015190080000 | L40: 015190080000 | N40: 007 | O40: 015 | Q40: 40030 | R40: U S A KNF | X40: 0 | Y40: 0 | Z40: 0 | AA40: 0 | AB40: 0 | AC40: 0 | AD40: 0 | AE40: 0 | AF40: 0 | AO40: 3 | AP40: 44N | AQ40: 11W | AS40: 2016I601 | AT40: 2016 | AU40: No | AV40: No | AW40: 15932.471 | AX40: TownofScottBar_Scott_Feds_Clip | AY40: 9743.3964 | AZ40: 5108223.6
A41: 40 | B41: 5148 | C41: 5148 | D41: 015-190-090 | E41: 518.40829 | F41: 015-190-09 | G41: 31675.236 | H41: 015190090000 | I41: 31675.236 | J41: 10833 | K41: 015190090000 | L41: 015190090000 | N41: 007 | O41: 015 | Q41: 40030 | R41: U S A KNF | X41: 0 | Y41: 0 | Z41: 0 | AA41: 0 | AB41: 0 | AC41: 0 | AD41: 0 | AE41: 0 | AF41: 0 | AO41: 2 | AP41: 44N | AQ41: 11W | AS41: 2016I601 | AT41: 2016 | AU41: No | AV41: No | AW41: 31675.236 | AX41: TownofScottBar_Scott_Feds_Clip | AY41: 31675.236 | AZ41: 22582167
A42: 41 | B42: 7228 | C42: 7228 | D42: 015-160-050 | E42: 229.84736 | F42: 015-160-05 | G42: 19841.953 | H42: 015160050000 | I42: 19841.953 | J42: 10814 | K42: 015160050000 | L42: 015160050000 | N42: 007 | O42: 015 | Q42: 40030 | R42: U S A KNF | X42: 0 | Y42: 0 | Z42: 0 | AA42: 0 | AB42: 0 | AC42: 0 | AD42: 0 | AE42: 0 | AF42: 0 | AO42: 23 | AP42: 45N | AQ42: 11W | AS42: 2016I601 | AT42: 2016 | AU42: No | AV42: No | AW42: 19841.953 | AX42: TownofScottBar_Scott_Feds_Clip | AY42: 14005.365 | AZ42: 10012257
A43: 42 | B43: 7229 | C43: 7229 | D43: 015-300-080 | E43: 630.04869 | F43: 015-300-08 | G43: 20958.389 | H43: 015300080000 | I43: 20958.39 | J43: 10928 | K43: 015300080000 | L43: 015300080000 | N43: 007 | O43: 015 | Q43: 40030 | R43: U S A KNF | X43: 0 | Y43: 0 | Z43: 0 | AA43: 0 | AB43: 0 | AC43: 0 | AD43: 0 | AE43: 0 | AF43: 0 | AO43: 20 | AP43: 45N | AQ43: 10W | AS43: 2016I601 | AT43: 2016 | AU43: No | AV43: No | AW43: 20958.39 | AX43: TownofScottBar_Scott_Feds_Clip | AY43: 20958.39 | AZ43: 27446346
A44: 43 | B44: 7275 | C44: 7275 | D44: 015-260-010 | E44: 344.80962 | F44: 015-260-01 | G44: 17043.443 | H44: 015260010000 | I44: 17043.443 | J44: 10628 | K44: 015260010000 | L44: 015260010000 | N44: 007 | O44: 015 | Q44: 40030 | R44: U S A KNF | X44: 0 | Y44: 0 | Z44: 0 | AA44: 0 | AB44: 0 | AC44: 0 | AD44: 0 | AE44: 0 | AF44: 0 | AO44: 5 | AP44: 45N | AQ44: 10W | AS44: 2016I601 | AT44: 2016 | AU44: No | AV44: No | AW44: 17043.443 | AX44: TownofScottBar_Scott_Feds_Clip | AY44: 16516.706 | AZ44: 15020378
A45: 44 | B45: 7565 | C45: 7565 | D45: 015-270-180 | E45: 0.024538516 | F45: 015-270-18 | G45: 159.45775 | H45: 015270180000 | I45: 159.45784 | J45: 10902 | K45: 015270180000 | L45: 015270180000 | N45: 007 | O45: 015 | Q45: 40030 | R45: U S A KNF | X45: 0 | Y45: 0 | Z45: 0 | AA45: 0 | AB45: 0 | AC45: 0 | AD45: 0 | AE45: 0 | AF45: 0 | AO45: 6 | AP45: 45N | AQ45: 10W | AS45: 2016I601 | AT45: 2016 | AU45: No | AV45: No | AW45: 159.45784 | AX45: TownofScottBar_Scott_Feds_Clip | AY45: 159.45784 | AZ45: 1068.9604
A46: 45 | B46: 7776 | C46: 7776 | D46: 015-260-020 | E46: 391.3589 | F46: 015-260-02 | G46: 16950.782 | H46: 015260020000 | I46: 16950.782 | J46: 10629 | K46: 015260020000 | L46: 015260020000 | N46: 007 | O46: 015 | Q46: 40030 | R46: U S A KNF | X46: 0 | Y46: 0 | Z46: 0 | AA46: 0 | AB46: 0 | AC46: 0 | AD46: 0 | AE46: 0 | AF46: 0 | AO46: 4 | AP46: 45N | AQ46: 10W | AS46: 2016I601 | AT46: 2016 | AU46: No | AV46: No | AW46: 16950.782 | AX46: TownofScottBar_Scott_Feds_Clip | AY46: 16680.208 | AZ46: 17048182
A47: 46 | B47: 8499 | C47: 8499 | D47: 015-500-070 | E47: 4.2650297 | F47: 015-500-07 | G47: 2238.4623 | H47: 015500070000 | I47: 2238.4622 | J47: 11149 | K47: 015500070000 | L47: 015500070000 | N47: 007 | O47: 015 | Q47: 40030 | R47: U S A KNF | X47: 0 | Y47: 0 | Z47: 0 | AA47: 0 | AB47: 0 | AC47: 0 | AD47: 0 | AE47: 0 | AF47: 0 | AO47: 16 | AP47: 45N | AQ47: 10W | AS47: 2016I601 | AT47: 2016 | AU47: No | AV47: No | AW47: 2238.4622 | AX47: TownofScottBar_Scott_Feds_Clip | AY47: 2238.4622 | AZ47: 185795.1
A48: 47 | B48: 8666 | C48: 8666 | D48: 015-330-070 | E48: 610.65745 | F48: 015-330-07 | G48: 20632.47 | H48: 015330070000 | I48: 20632.471 | J48: 10679 | K48: 015330070000 | L48: 015330070000 | N48: 007 | O48: 015 | Q48: 40030 | R48: U S A KNF | X48: 0 | Y48: 0 | Z48: 0 | AA48: 0 | AB48: 0 | AC48: 0 | AD48: 0 | AE48: 0 | AF48: 0 | AO48: 34 | AP48: 45N | AQ48: 10W | AS48: 2016I601 | AT48: 2016 | AU48: No | AV48: No | AW48: 20632.471 | AX48: TownofScottBar_Scott_Feds_Clip | AY48: 20632.471 | AZ48: 26600795
A49: 48 | B49: 10179 | C49: 10179 | D49: 015-350-130 | E49: 596.77409 | F49: 015-350-13 | G49: 20394.165 | H49: 015350130000 | I49: 20394.165 | J49: 10687 | K49: 015350130000 | L49: 015350130000 | N49: 007 | O49: 015 | Q49: 40030 | R49: U S A KNF | X49: 0 | Y49: 0 | Z49: 0 | AA49: 0 | AB49: 0 | AC49: 0 | AD49: 0 | AE49: 0 | AF49: 0 | AO49: 30 | AP49: 45N | AQ49: 10W | AS49: 2016I601 | AT49: 2016 | AU49: No | AV49: No | AW49: 20394.165 | AX49: TownofScottBar_Scott_Feds_Clip | AY49: 20394.165 | AZ49: 25996239
A50: 49 | B50: 10440 | C50: 10440 | D50: 015-280-160 | E50: 575.04598 | F50: 015-280-16 | G50: 20600.44 | H50: 015280160000 | I50: 20600.44 | J50: 10913 | K50: 015280160000 | L50: 015280160000 | N50: 007 | O50: 015 | Q50: 40030 | R50: U S A KNF | X50: 0 | Y50: 0 | Z50: 0 | AA50: 0 | AB50: 0 | AC50: 0 | AD50: 0 | AE50: 0 | AF50: 0 | AO50: 7 | AP50: 45N | AQ50: 10W | AS50: 2016I601 | AT50: 2016 | AU50: No | AV50: No | AW50: 20600.44 | AX50: TownofScottBar_Scott_Feds_Clip | AY50: 20051.299 | AZ50: 25049904
...

Sheet Pivot Table Feds
A1: HUC12 | B1: SUM of GIS_ACRES
A2: Boulder-Scott_Feds__Clip | B2: 7000.8922
A3: Canyon_Feds_Clip | B3: 15596.344
A4: Clark_Scott_Feds_Clip | B4: 166.26342
A5: Etna_Feds_Clip | B5: 7785.3462
A6: French_Feds_Clip | B6: 6040.2565
A7: Indian_Feds_Clip | B7: 8065.3467
A8: Kelsey_Feds_Clip | B8: 11293.657
A9: Kidder_Feds_Clip | B9: 8020.2839
A10: LowerEast_Feds_Clip | B10: 10254.197
A11: LowerMoffett_Feds_Clip | B11: 2200.0559
A12: McAdams_Feds_Clip | B12: 8722.8715
A13: Mill_Feds_Clip | B13: 6750.5491
... A25: Grand Total | B25: 181908.36

Sheet EFM_Sugar_NoValleyClip_Merge
A1: OBJECTID_12 | B1: OBJECTID_1 | C1: OBJECTID | D1: APN | E1: GIS_ACRES | F1: Apn_join | G1: Shape_Leng | H1: ASMT | I1: Shape_Le_1 | J1: OBJECTID_2 | K1: Asmt_1 | L1: FeeParcel | M1: Zoning1 | N1: LandUse1 | O1: Neighborho | P1: CurrentDoc | Q1: CurrentD_1 | R1: AssesseeNa | S1: DBA | T1: Address1 | U1: Address2 | V1: Address3 | W1: Address4 | X1: LastOfLand | Y1: LastOfStru | Z1: LastOfFixt | AA1: LastOfFi_1 | AB1: LastOfPPBu | AC1: LastOfPPMH | AD1: LastOfHOXE | AE1: LastOfOthe | AF1: NetAssesse | AG1: LastOfOt_1 | AH1: Street | AI1: StreetNum | AJ1: StreetType | AK1: StreetDire | AL1: SpaceApt | AM1: Community | AN1: Zip | AO1: Sec | AP1: Township | AQ1: Range | AR1: Descr | AS1: LastOfDocN | AT1: RollYear | AU1: TimberPres | AV1: AgPreserve | AW1: Shape_Le_2 | AX1: MERGE_SRC | AY1: Shape_Length | AZ1: Shape_Area
A2: 1 | B2: 1438 | C2: 1438 | D2: 031-120-010 | E2: 4570.6924 | F2: 031-120-01 | G2: 21478.145 | H2: 031120010000 | I2: 21478.145 | J2: 23091 | K2: 031120010000 | L2: 031120010000 | N2: 888 | O2: 031 | P2: 2006R0009470 | Q2: 38910 | R2: TIMBERVEST PARTNERS CALIFORNIA LLC | T2: 3715 NORTHSIDE PARKWAY BLD 200 SUITE 500 | U2: ATLANTA GA 30327 | X2: 28160 | Y2: 0 | Z2: 0 | AA2: 0 | AB2: 0 | AC2: 0 | AD2: 0 | AE2: 0 | AF2: 28160 | AO2: 33 | AP2: 40N | AQ2: 9W | AS2: 2016I601 | AT2: 2016 | AU2: Yes | AV2: No | AW2: 21478.145 | AX2: Sugar | AY2: 183720.32 | AZ2: 1.9907121e+08
A3: 2 | B3: 1438 | C3: 1438 | D3: 031-120-010 | E3: 641.09598 | F3: 031-120-01 | G3: 21478.145 | H3: 031120010000 | I3: 21478.145 | J3: 23091 | K3: 031120010000 | L3: 031120010000 | N3: 888 | O3: 031 | P3: 2006R0009470 | Q3: 38910 | R3: TIMBERVEST PARTNERS CALIFORNIA LLC | T3: 3715 NORTHSIDE PARKWAY BLD 200 SUITE 500 | U3: ATLANTA GA 30327 | X3: 28160 | Y3: 0 | Z3: 0 | AA3: 0 | AB3: 0 | AC3: 0 | AD3: 0 | AE3: 0 | AF3: 28160 | AO3: 33 | AP3: 40N | AQ3: 9W | AS3: 2016I601 | AT3: 2016 | AU3: Yes | AV3: No | AW3: 21478.145 | AX3: SouthFork | AY3: 34740.535 | AZ3: 27921286
A4: 3 | B4: 20051 | C4: 20051 | D4: 023-150-030 | E4: 3375.1005 | F4: 023-150-03 | G4: 7880.913 | H4: 023150030000 | I4: 7880.913 | J4: 17716 | K4: 023150030000 | L4: 023150030000 | N4: 888 | O4: 023 | P4: 2006R0009470 | Q4: 38910 | R4: TIMBERVEST PARTNERS CALIFORNIA LLC | T4: 3715 NORTHSIDE PARKWAY BLD 200 SUITE 500 | U4: ATLANTA GA 30327 | X4: 2879 | Y4: 0 | Z4: 0 | AA4: 0 | AB4: 0 | AC4: 0 | AD4: 0 | AE4: 0 | AF4: 2879 | AO4: 6 | AP4: 41N | AQ4: 9W | AS4: 2016I601 | AT4: 2016 | AU4: Yes | AV4: No | AW4: 7880.913 | AX4: Snicktaw | AY4: 58431.412 | AZ4: 1.4701527e+08
A5: 4 | B5: 20051 | C5: 20051 | D5: 023-150-030 | E5: 9465.5082 | F5: 023-150-03 | G5: 7880.913 | H5: 023150030000 | I5: 7880.913 | J5: 17716 | K5: 023150030000 | L5: 023150030000 | N5: 888 | O5: 023 | P5: 2006R0009470 | Q5: 38910 | R5: TIMBERVEST PARTNERS CALIFORNIA LLC | T5: 3715 NORTHSIDE PARKWAY BLD 200 SUITE 500 | U5: ATLANTA GA 30327 | X5: 2879 | Y5: 0 | Z5: 0 | AA5: 0 | AB5: 0 | AC5: 0 | AD5: 0 | AE5: 0 | AF5: 2879 | AO5: 6 | AP5: 41N | AQ5: 9W | AS5: 2016I601 | AT5: 2016 | AU5: Yes | AV5: No | AW5: 7880.913 | AX5: Shackleford | AY5: 117681.11 | AZ5: 4.1229649e+08
